Workbook

Sheet 버킷분류
A1: 진영 | B1: 버킷 | C1: 버킷명 | D1: 티커 | E1: ETF명 | F1: AUM(억원) | G1: 기초지수 | H1: 원본_위험안전 | I1: 원본_자산군 | J1: 대표ETF
A2: 방어 | B2: A1 | C2: 현금성 | D2: A459580 | E2: KODEX CD금리액티브(합성) | F2: 79731 | G2: KAP 양도성예금증서(CD)금리지수(총수익지수) | H2: 안전 | I2: 금리연계형/초단기채권 | J2: ★
A3: 방어 | B3: A1 | C3: 현금성 | D3: A488770 | E3: KODEX 머니마켓액티브 | F3: 72891 | G3: KAP MMF 지수(TR) | H3: 안전 | I3: 금리연계형/초단기채권
A4: 방어 | B4: A1 | C4: 현금성 | D4: A423160 | E4: KODEX KOFR금리액티브(합성) | F4: 43045 | G4: KOFR 지수 | H4: 안전 | I4: 금리연계형/초단기채권
A5: 방어 | B5: A1 | C5: 현금성 | D5: A455890 | E5: RISE 머니마켓액티브 | F5: 22406 | G5: KIS 시가평가 MMF 지수 (총수익지수) | H5: 안전 | I5: 금리연계형/초단기채권
A6: 방어 | B6: A1 | C6: 현금성 | D6: A0061Z0 | E6: RISE 단기특수은행채액티브 | F6: 12843 | G6: KAP 단기 특수은행채 지수(시장가격) | H6: 안전 | I6: 국내채권_회사채
A7: 방어 | B7: A1 | C7: 현금성 | D7: A157450 | E7: TIGER 단기통안채 | F7: 9750 | G7: KIS MSB 6M(총수익) | H7: 안전 | I7: 국내채권_종합
A8: 방어 | B8: A1 | C8: 현금성 | D8: A469830 | E8: SOL 초단기채권액티브 | F8: 9092 | G8: KAP 단기자금시장지수 | H8: 안전 | I8: 금리연계형/초단기채권
A9: 방어 | B9: A1 | C9: 현금성 | D9: A153130 | E9: KODEX 단기채권 | F9: 7321 | G9: KRW Cash Index(총수익) | H9: 안전 | I9: 금리연계형/초단기채권
A10: 방어 | B10: A1 | C10: 현금성 | D10: A456610 | E10: TIGER 미국달러SOFR금리액티브(합성) | F10: 6550 | G10: Solactive SOFR Daily Total Return Index | H10: 안전 | I10: 금리연계형/초단기채권
A11: 방어 | B11: A1 | C11: 현금성 | D11: A329750 | E11: TIGER 미국달러단기채권액티브 | F11: 4708 | G11: KIS U.S. TREASURY BOND 0-1Y 지수 | H11: 안전 | I11: 해외채권_종합
A12: 방어 | B12: A1 | C12: 현금성 | D12: A196230 | E12: RISE 단기통안채 | F12: 2081 | G12: KIS MSB 5M Index(총수익) | H12: 안전 | I12: 금리연계형/초단기채권
A13: 방어 | B13: A1 | C13: 현금성 | D13: A272560 | E13: RISE 단기국공채액티브 | F13: 1915 | G13: KIS 종합채권국공채3M~1.5Y지수 | H13: 안전 | I13: 국내채권_종합
A14: 방어 | B14: A1 | C14: 현금성 | D14: A455960 | E14: RISE 미국달러SOFR금리액티브(합성) | F14: 602 | G14: KAP SOFR 지수 | H14: 안전 | I14: 금리연계형/초단기채권
A15: 방어 | B15: A1 | C15: 현금성 | D15: A278620 | E15: PLUS 단기채권액티브 | F15: 532 | G15: KAP 투자적격 크레딧 채권 1년지수(A-이상,총수익) | H15: 안전 | I15: 국내채권_회사채
A16: 방어 | B16: A2 | C16: 국내 금리(국채·IG) | D16: A273130 | E16: KODEX 종합채권(AA-이상)액티브 | F16: 38484 | G16: KAP 한국종합채권지수 | H16: 안전 | I16: 국내채권_회사채 | J16: ★
A17: 방어 | B17: A2 | C17: 국내 금리(국채·IG) | D17: A385540 | E17: RISE 종합채권(A-이상)액티브 | F17: 17737 | G17: KIS 종합채권 지수(A-이상)(총수익지수) | H17: 안전 | I17: 국내채권_회사채
A18: 방어 | B18: A2 | C18: 국내 금리(국채·IG) | D18: A451540 | E18: TIGER 종합채권(AA-이상)액티브 | F18: 10134 | G18: KIS 종합채권 AA-이상 총수익 지수(Total return Index) | H18: 안전 | I18: 국내채권_회사채
A19: 방어 | B19: A2 | C19: 국내 금리(국채·IG) | D19: A438330 | E19: TIGER 투자등급회사채액티브 | F19: 6984 | G19: KIS 투자등급회사채 지수(총수익) | H19: 안전 | I19: 국내채권_회사채
A20: 방어 | B20: A2 | C20: 국내 금리(국채·IG) | D20: A114260 | E20: KODEX 국고채3년 | F20: 5353 | G20: MKF 국고채지수(총수익) | H20: 안전 | I20: 국내채권_종합
A21: 방어 | B21: A2 | C21: 국내 금리(국채·IG) | D21: A148070 | E21: KIWOOM 국고채10년 | F21: 4925 | G21: KIS 국고채 10년(총수익) | H21: 안전 | I21: 국내채권_종합
A22: 방어 | B22: A2 | C22: 국내 금리(국채·IG) | D22: A0016X0 | E22: SOL 중단기회사채(A-이상)액티브 | F22: 3669 | G22: KIS 중단기크레딧플러스채권(AA+~A-)지수(총수익) | H22: 안전 | I22: 국내채권_회사채
A23: 방어 | B23: A2 | C23: 국내 금리(국채·IG) | D23: A439870 | E23: KODEX 국고채30년액티브 | F23: 3549 | G23: KAP 국고채 30년 총수익 지수 | H23: 안전 | I23: 국내채권_종합
A24: 방어 | B24: A2 | C24: 국내 금리(국채·IG) | D24: A363570 | E24: KODEX 장기종합채권(AA-이상)액티브 | F24: 3200 | G24: KAP 한국장기종합채권지수(AA-이상, 총수익) | H24: 안전 | I24: 국내채권_회사채
A25: 방어 | B25: A2 | C25: 국내 금리(국채·IG) | D25: A302190 | E25: TIGER 중장기국채 | F25: 2950 | G25: KIS 국채 3-10년 지수(시장가격지수) | H25: 안전 | I25: 국내채권_종합
A26: 방어 | B26: A2 | C26: 국내 금리(국채·IG) | D26: A114100 | E26: RISE 국고채3년 | F26: 1798 | G26: KTB index(시장가격) | H26: 안전 | I26: 국내채권_종합
A27: 방어 | B27: A2 | C27: 국내 금리(국채·IG) | D27: A451530 | E27: TIGER 국고채30년스트립액티브 | F27: 1444 | G27: KIS STRIP 30Y Index(총수익지수) | H27: 안전 | I27: 국내채권_종합
A28: 방어 | B28: A2 | C28: 국내 금리(국채·IG) | D28: A298340 | E28: PLUS 국채선물3년 | F28: 600 | G28: F-KTB 지수 | H28: 안전 | I28: 국내채권_종합
... A32: 방어 | B32: A2 | C32: 국내 금리(국채·IG) | D32: A397420 | E32: RISE 국채선물5년추종 | F32: 52 | G32: 5년 국채선물 추종 지수 | H32: 안전 | I32: 국내채권_종합
A33: 방어 | B33: A3 | C33: 미국 금리(국채·IG) | D33: A453850 | E33: ACE 미국30년국채액티브(H) | F33: 18200 | G33: Bloomberg U.S Treasury 20+ Year Total Return Index | H33: 안전 | I33: 해외채권_종합 | J33: ★
A34: 방어 | B34: A3 | C34: 미국 금리(국채·IG) | D34: A458250 | E34: TIGER 미국30년국채스트립액티브(합성 H) | F34: 6231 | G34: ICE BofA Long US Treasury Principal STRIPS Index | H34: 안전 | I34: 해외채권_종합
A35: 방어 | B35: A3 | C35: 미국 금리(국채·IG) | D35: A484790 | E35: KODEX 미국30년국채액티브(H) | F35: 5934 | G35: KEDI-KAP 미국 국채 20+ 지수(TR) | H35: 안전 | I35: 해외채권_종합
A36: 방어 | B36: A3 | C36: 미국 금리(국채·IG) | D36: A472870 | E36: RISE 미국30년국채엔화노출(합성 H) | F36: 3570 | G36: KIS 미국채30년 엔화노출 지수(USD/JPY 헤지)(총수익지수) | H36: 안전 | I36: 해외채권_종합
A37: 방어 | B37: A3 | C37: 미국 금리(국채·IG) | D37: A476760 | E37: ACE 미국30년국채액티브 | F37: 3171 | G37: Bloomberg U.S Treasury 20+ Year Total Return Index | H37: 안전 | I37: 해외채권_종합
A38: 방어 | B38: A3 | C38: 미국 금리(국채·IG) | D38: A458260 | E38: TIGER 미국투자등급회사채액티브(H) | F38: 2883 | G38: iBoxx USD Liquid Investment Grade Index(Price Return) | H38: 안전 | I38: 해외채권_회사채
A39: 방어 | B39: A3 | C39: 미국 금리(국채·IG) | D39: A305080 | E39: TIGER 미국채10년선물 | F39: 2446 | G39: S&P 10-Year U.S. Treasury Note Futures(ER) | H39: 안전 | I39: 해외채권_종합
A40: 방어 | B40: A3 | C40: 미국 금리(국채·IG) | D40: A308620 | E40: KODEX 미국10년국채선물 | F40: 1138 | G40: S&P 10-Year U.S. Treasury Note Futures KRW(ER) | H40: 안전 | I40: 해외채권_종합
A41: 방어 | B41: A3 | C41: 미국 금리(국채·IG) | D41: A476750 | E41: ACE 미국30년국채엔화노출액티브(H) | F41: 860 | G41: Bloomberg U.S. Treasury 20+ Year Total Return Index T1530 JPY Currency Hedged | H41: 안전 | I41: 해외채권_종합
A42: 방어 | B42: A3 | C42: 미국 금리(국채·IG) | D42: A468630 | E42: KODEX iShares미국투자등급회사채액티브 | F42: 367 | G42: Markit iBoxx USD Liquid Investment Grade Index(Total Return) | H42: 안전 | I42: 해외채권_회사채
A43: 방어 | B43: A3 | C43: 미국 금리(국채·IG) | D43: A332620 | E43: PLUS 미국장기우량회사채 | F43: 208 | G43: ICE BofaAML 15+ Year AAA-A US Corporate Index(총수익지수) | H43: 안전 | I43: 해외채권_회사채
...

Sheet 버킷요약
A1: 버킷 | B1: 버킷명 | C1: 진영 | D1: 종목수 | E1: AUM합(억원) | F1: AUM비중 | G1: 대표ETF
A2: A1 | B2: 현금성 | C2: 방어 | D2: =COUNTIF(버킷분류!B2:B189,A2) -> 14 | E2: =SUMIF(버킷분류!B2:B189,A2,버킷분류!F2:F189) -> 273467 | F2: =E2/$E$17 -> 0.13386805 | G2: KODEX CD금리액티브(합성)
A3: A2 | B3: 국내 금리(국채·IG) | C3: 방어 | D3: =COUNTIF(버킷분류!B2:B189,A3) -> 17 | E3: =SUMIF(버킷분류!B2:B189,A3,버킷분류!F2:F189) -> 102228 | F3: =E3/$E$17 -> 0.050042833 | G3: KODEX 종합채권(AA-이상)액티브
A4: A3 | B4: 미국 금리(국채·IG) | C4: 방어 | D4: =COUNTIF(버킷분류!B2:B189,A4) -> 13 | E4: =SUMIF(버킷분류!B2:B189,A4,버킷분류!F2:F189) -> 45190 | F4: =E4/$E$17 -> 0.02212149 | G4: ACE 미국30년국채액티브(H)
A5: A4 | B5: 안전통화 | C5: 방어 | D5: =COUNTIF(버킷분류!B2:B189,A5) -> 3 | E5: =SUMIF(버킷분류!B2:B189,A5,버킷분류!F2:F189) -> 1485 | F5: =E5/$E$17 -> 0.00072693985 | G5: KODEX 미국달러선물
A6: A5 | B6: 금·인플레헤지 | C6: 방어 | D6: =COUNTIF(버킷분류!B2:B189,A6) -> 5 | E6: =SUMIF(버킷분류!B2:B189,A6,버킷분류!F2:F189) -> 72014 | F6: =E6/$E$17 -> 0.035252422 | G6: ACE KRX금현물
A7: B1 | B7: 한국주식(브로드·시클리컬·테마) | C7: 성장 | D7: =COUNTIF(버킷분류!B2:B189,A7) -> 34 | E7: =SUMIF(버킷분류!B2:B189,A7,버킷분류!F2:F189) -> 637558 | F7: =E7/$E$17 -> 0.31209853 | G7: KODEX 200
A8: B2 | B8: 미국·선진 코어주식 | C8: 성장 | D8: =COUNTIF(버킷분류!B2:B189,A8) -> 24 | E8: =SUMIF(버킷분류!B2:B189,A8,버킷분류!F2:F189) -> 466250 | F8: =E8/$E$17 -> 0.22823953 | G8: TIGER 미국S&P500
A9: B3 | B9: 글로벌 테크·반도체·성장테마 | C9: 성장 | D9: =COUNTIF(버킷분류!B2:B189,A9) -> 24 | E9: =SUMIF(버킷분류!B2:B189,A9,버킷분류!F2:F189) -> 311193 | F9: =E9/$E$17 -> 0.15233575 | G9: TIGER 미국테크TOP10 INDXX
A10: B4 | B10: 중국주식 | C10: 성장 | D10: =COUNTIF(버킷분류!B2:B189,A10) -> 10 | E10: =SUMIF(버킷분류!B2:B189,A10,버킷분류!F2:F189) -> 19658 | F10: =E10/$E$17 -> 0.0096230193 | G10: TIGER 차이나항셍테크
A11: B5 | B11: 기타 해외주식 | C11: 성장 | D11: =COUNTIF(버킷분류!B2:B189,A11) -> 18 | E11: =SUMIF(버킷분류!B2:B189,A11,버킷분류!F2:F189) -> 21328 | F11: =E11/$E$17 -> 0.010440521 | G11: TIGER 일본니케이225
A12: B6 | B12: 방어적 주식(배당·저변동) | C12: 성장 | D12: =COUNTIF(버킷분류!B2:B189,A12) -> 17 | E12: =SUMIF(버킷분류!B2:B189,A12,버킷분류!F2:F189) -> 86293 | F12: =E12/$E$17 -> 0.042242303 | G12: TIGER 미국배당다우존스
A13: B7 | B13: 리츠(부동산) | C13: 성장 | D13: =COUNTIF(버킷분류!B2:B189,A13) -> 2 | E13: =SUMIF(버킷분류!B2:B189,A13,버킷분류!F2:F189) -> 1998 | F13: =E13/$E$17 -> 0.00097806453 | G13: TIGER 미국MSCI리츠(합성 H)
A14: B8 | B14: 경기민감 원자재·에너지 | C14: 성장 | D14: =COUNTIF(버킷분류!B2:B189,A14) -> 4 | E14: =SUMIF(버킷분류!B2:B189,A14,버킷분류!F2:F189) -> 2378 | F14: =E14/$E$17 -> 0.0011640828 | G14: KODEX WTI원유선물(H)
A15: B9 | B15: 위험 크레딧(하이일드) | C15: 성장 | D15: =COUNTIF(버킷분류!B2:B189,A15) -> 3 | E15: =SUMIF(버킷분류!B2:B189,A15,버킷분류!F2:F189) -> 1770 | F15: =E15/$E$17 -> 0.00086645356 | G15: KODEX iShares미국하이일드액티브
A17: 합계 | D17: =SUM(D2:D15) -> 188 | E17: =SUM(E2:E15) -> 2042810
